<?xml version="1.0" encoding="utf-8"?>

<robot name="ur5">

    <link name="world"/>
    <link name="base_link">
        <visual>
            <origin xyz="0 0 0" rpy="0 0 ${pi}"/>
            <geometry>
                <mesh filename="package://meshes/ur5/visual/base.dae"/>
            </geometry>
        </visual>
        <collision>
            <origin xyz="0 0 0" rpy="0 0 ${pi}"/>
            <geometry>
                <mesh filename="package://meshes/ur5/collision/base.stl"/>
            </geometry>
        </collision>
    </link>

    <joint name="joint_world" type="fixed">
        <parent link="world"/>
        <child link="base_link"/>
        <origin rpy="0 0 3.141592653589793" xyz="0 0 0" />
    </joint>

    <link name="shoulder_link">
        <visual>
            <origin xyz="0 0 0" rpy="0 0 3.141592653589793"/>
            <geometry>
                <mesh filename="package://meshes/ur5/visual/shoulder.dae"/>
            </geometry>
        </visual>
        <collision>
            <origin xyz="0 0 0" rpy="0 0 3.141592653589793"/>
            <geometry>
                <mesh filename="package://meshes/ur5/collision/shoulder.stl"/>
            </geometry>
        </collision>
    </link>

    <joint name="joint1" type="revolute">
        <!-- 0.089159 -->
        <origin rpy="0 0 0" xyz="0 0 0.089159" />
        <axis xyz="0 0 1" />
        <parent link="base_link" />
        <child link="shoulder_link"/>
        <!-- -360 - 360 -->
        <limit effort="1" velocity="1.0" lower="-6.28" upper="6.28" />
    </joint>

    <link name="upperarm_link">
        <visual>
            <origin rpy="1.5707963267948966 0 -1.5707963267948966" xyz="0 0 0.13585" />
            <geometry>
                <mesh filename="package://meshes/ur5/visual/upperarm.dae"/>
            </geometry>
        </visual>
        <collision>
            <origin rpy="1.5707963267948966 0 -1.5707963267948966" xyz="0 0 0.13585" />
            <geometry>
                <mesh filename="package://meshes/ur5/collision/upperarm.stl"/>
            </geometry>
        </collision>
    </link>

    <joint name="joint2" type="revolute">
        <!-- 0.089159 -->
        <origin rpy="1.570796327 0 0" xyz="0 0 0" />
        <axis xyz="0 0 1" />
        <parent link="shoulder_link" />
        <child link="upperarm_link"/>
        <!-- -360 - 360 -->
        <limit effort="30" velocity="1.0" lower="-6.28" upper="6.28" />
    </joint>

    <link name="forearm_link">
        <visual>
            <origin rpy="1.5707963267948966 0 -1.5707963267948966" xyz="0 0 0.0165" />
            <geometry>
                <mesh filename="package://meshes/ur5/visual/forearm.dae"/>
            </geometry>
        </visual>
        <collision>
            <origin rpy="1.5707963267948966 0 -1.5707963267948966" xyz="0 0 0.0165" />
            <geometry>
                <mesh filename="package://meshes/ur5/collision/forearm.stl"/>
            </geometry>
        </collision>
    </link>

    <joint name="joint3" type="revolute">
        <!-- 0.089159 -->
        <origin rpy="0 0 0" xyz="-0.425 0 0" />
        <axis xyz="0 0 1" />
        <parent link="upperarm_link" />
        <child link="forearm_link"/>
        <!-- -360 - 360 -->
        <limit effort="30" velocity="1.0" lower="-6.28" upper="6.28" />
    </joint>

    <link name="wrist1_link">
        <visual>
            <origin rpy="1.5707963267948966 0 0" xyz="0 0 -0.093" />
            <geometry>
                <mesh filename="package://meshes/ur5/visual/wrist1.dae"/>
            </geometry>
        </visual>
        <collision>
            <origin rpy="1.5707963267948966 0 0" xyz="0 0 -0.093" />
            <geometry>
                <mesh filename="package://meshes/ur5/collision/wrist1.stl"/>
            </geometry>
        </collision>
    </link>

    <joint name="joint4" type="revolute">
        <!-- 0.089159 -->
        <origin rpy="0 0 0" xyz="-0.39225 0 0.10915" />
        <axis xyz="0 0 1" />
        <parent link="forearm_link" />
        <child link="wrist1_link"/>
        <!-- -360 - 360 -->
        <limit effort="30" velocity="1.0" lower="-6.28" upper="6.28" />
    </joint>

    <link name="wrist2_link">
        <visual>
            <origin rpy="0 0 0" xyz="0 0 -0.095" />
            <geometry>
                <mesh filename="package://meshes/ur5/visual/wrist2.dae"/>
            </geometry>
        </visual>
        <collision>
            <origin rpy="0 0 0" xyz="0 0 -0.095" />
            <geometry>
                <mesh filename="package://meshes/ur5/collision/wrist2.stl"/>
            </geometry>
        </collision>
    </link>

    <joint name="joint5" type="revolute">
        <!-- 0.089159 -->
        <origin rpy="1.570796327 0 0" xyz="0 -0.09465 -1.941303950897609e-11" />
        <axis xyz="0 0 1" />
        <parent link="wrist1_link" />
        <child link="wrist2_link"/>
        <!-- -360 - 360 -->
        <limit effort="30" velocity="1.0" lower="-6.28" upper="6.28" />
    </joint>

    <link name="wrist3_link">
        <visual>
            <origin rpy="1.5707963267948966 0 0" xyz="0 0 -0.0818" />
            <geometry>
                <mesh filename="package://meshes/ur5/visual/wrist3.dae"/>
            </geometry>
        </visual>
        <collision>
            <origin rpy="1.5707963267948966 0 0" xyz="0 0 -0.0818" />
            <geometry>
                <mesh filename="package://meshes/ur5/collision/wrist3.stl"/>
            </geometry>
        </collision>
    </link>

    <joint name="joint6" type="revolute">
        <!-- 0.089159 -->
        <origin rpy="1.570796326589793 3.141592653589793 3.141592653589793" xyz="0 0.0823 -1.688001216681175e-11" />
        <axis xyz="0 0 1" />
        <parent link="wrist2_link" />
        <child link="wrist3_link"/>
        <!-- -360 - 360 -->
        <limit effort="30" velocity="1.0" lower="-6.28" upper="6.28" />
    </joint>

</robot>
